[2023-12-21T21:06:03.719+0000] {taskinstance.py:1159} INFO - Dependencies all met for dep_context=non-requeueable deps ti=<TaskInstance: pizza_order_dag.confirm_order_task manual__2023-12-21T21:06:01.515284+00:00 [queued]>
[2023-12-21T21:06:03.727+0000] {taskinstance.py:1159} INFO - Dependencies all met for dep_context=requeueable deps ti=<TaskInstance: pizza_order_dag.confirm_order_task manual__2023-12-21T21:06:01.515284+00:00 [queued]>
[2023-12-21T21:06:03.728+0000] {taskinstance.py:1361} INFO - Starting attempt 1 of 1
[2023-12-21T21:06:03.742+0000] {taskinstance.py:1382} INFO - Executing <Task(_PythonDecoratedOperator): confirm_order_task> on 2023-12-21 21:06:01.515284+00:00
[2023-12-21T21:06:03.746+0000] {standard_task_runner.py:57} INFO - Started process 376 to run task
[2023-12-21T21:06:03.749+0000] {standard_task_runner.py:84} INFO - Running: ['***', 'tasks', 'run', 'pizza_order_dag', 'confirm_order_task', 'manual__2023-12-21T21:06:01.515284+00:00', '--job-id', '33', '--raw', '--subdir', 'DAGS_FOLDER/pizza_order_dag.py', '--cfg-path', '/tmp/tmplii2ttoa']
[2023-12-21T21:06:03.750+0000] {standard_task_runner.py:85} INFO - Job 33: Subtask confirm_order_task
[2023-12-21T21:06:03.789+0000] {task_command.py:416} INFO - Running <TaskInstance: pizza_order_dag.confirm_order_task manual__2023-12-21T21:06:01.515284+00:00 [running]> on host 20e184a2eb37
[2023-12-21T21:06:03.860+0000] {taskinstance.py:1662} INFO - Exporting env vars: AIRFLOW_CTX_DAG_OWNER='***' AIRFLOW_CTX_DAG_ID='pizza_order_dag' AIRFLOW_CTX_TASK_ID='confirm_order_task' AIRFLOW_CTX_EXECUTION_DATE='2023-12-21T21:06:01.515284+00:00' AIRFLOW_CTX_TRY_NUMBER='1' AIRFLOW_CTX_DAG_RUN_ID='manual__2023-12-21T21:06:01.515284+00:00'
[2023-12-21T21:06:03.952+0000] {taskinstance.py:1937} ERROR - Task failed with exception
Traceback (most recent call last):
  File "/home/airflow/.local/lib/python3.8/site-packages/airflow/decorators/base.py", line 221, in execute
    return_value = super().execute(context)
  File "/home/airflow/.local/lib/python3.8/site-packages/airflow/operators/python.py", line 192, in execute
    return_value = self.execute_callable()
  File "/home/airflow/.local/lib/python3.8/site-packages/airflow/operators/python.py", line 209, in execute_callable
    return self.python_callable(*self.op_args, **self.op_kwargs)
  File "/opt/airflow/dags/pizza_order_dag.py", line 38, in confirm_order
    django.setup()
  File "/home/airflow/.local/lib/python3.8/site-packages/django/__init__.py", line 19, in setup
    configure_logging(settings.LOGGING_CONFIG, settings.LOGGING)
  File "/home/airflow/.local/lib/python3.8/site-packages/django/conf/__init__.py", line 102, in __getattr__
    self._setup(name)
  File "/home/airflow/.local/lib/python3.8/site-packages/django/conf/__init__.py", line 89, in _setup
    self._wrapped = Settings(settings_module)
  File "/home/airflow/.local/lib/python3.8/site-packages/django/conf/__init__.py", line 217, in __init__
    mod = importlib.import_module(self.SETTINGS_MODULE)
  File "/usr/local/lib/python3.8/importlib/__init__.py", line 127, in import_module
    return _bootstrap._gcd_import(name[level:], package, level)
  File "<frozen importlib._bootstrap>", line 1014, in _gcd_import
  File "<frozen importlib._bootstrap>", line 991, in _find_and_load
  File "<frozen importlib._bootstrap>", line 961, in _find_and_load_unlocked
  File "<frozen importlib._bootstrap>", line 219, in _call_with_frames_removed
  File "<frozen importlib._bootstrap>", line 1014, in _gcd_import
  File "<frozen importlib._bootstrap>", line 991, in _find_and_load
  File "<frozen importlib._bootstrap>", line 961, in _find_and_load_unlocked
  File "<frozen importlib._bootstrap>", line 219, in _call_with_frames_removed
  File "<frozen importlib._bootstrap>", line 1014, in _gcd_import
  File "<frozen importlib._bootstrap>", line 991, in _find_and_load
  File "<frozen importlib._bootstrap>", line 973, in _find_and_load_unlocked
ModuleNotFoundError: No module named 'shpak'
[2023-12-21T21:06:03.962+0000] {taskinstance.py:1400} INFO - Marking task as FAILED. dag_id=pizza_order_dag, task_id=confirm_order_task, execution_date=20231221T210601, start_date=20231221T210603, end_date=20231221T210603
[2023-12-21T21:06:03.975+0000] {standard_task_runner.py:104} ERROR - Failed to execute job 33 for task confirm_order_task (No module named 'shpak'; 376)
[2023-12-21T21:06:04.002+0000] {local_task_job_runner.py:228} INFO - Task exited with return code 1
[2023-12-21T21:06:04.016+0000] {taskinstance.py:2778} INFO - 0 downstream tasks scheduled from follow-on schedule check
