[2023-12-21T21:43:11.379+0000] {taskinstance.py:1159} INFO - Dependencies all met for dep_context=non-requeueable deps ti=<TaskInstance: pizza_order_dag.confirm_order_task manual__2023-12-21T21:43:09.440852+00:00 [queued]>
[2023-12-21T21:43:11.388+0000] {taskinstance.py:1159} INFO - Dependencies all met for dep_context=requeueable deps ti=<TaskInstance: pizza_order_dag.confirm_order_task manual__2023-12-21T21:43:09.440852+00:00 [queued]>
[2023-12-21T21:43:11.389+0000] {taskinstance.py:1361} INFO - Starting attempt 1 of 1
[2023-12-21T21:43:11.401+0000] {taskinstance.py:1382} INFO - Executing <Task(_PythonDecoratedOperator): confirm_order_task> on 2023-12-21 21:43:09.440852+00:00
[2023-12-21T21:43:11.405+0000] {standard_task_runner.py:57} INFO - Started process 1012 to run task
[2023-12-21T21:43:11.408+0000] {standard_task_runner.py:84} INFO - Running: ['***', 'tasks', 'run', 'pizza_order_dag', 'confirm_order_task', 'manual__2023-12-21T21:43:09.440852+00:00', '--job-id', '59', '--raw', '--subdir', 'DAGS_FOLDER/pizza_order_dag.py', '--cfg-path', '/tmp/tmpiby87doh']
[2023-12-21T21:43:11.409+0000] {standard_task_runner.py:85} INFO - Job 59: Subtask confirm_order_task
[2023-12-21T21:43:11.447+0000] {task_command.py:416} INFO - Running <TaskInstance: pizza_order_dag.confirm_order_task manual__2023-12-21T21:43:09.440852+00:00 [running]> on host 20e184a2eb37
[2023-12-21T21:43:11.526+0000] {taskinstance.py:1662} INFO - Exporting env vars: AIRFLOW_CTX_DAG_OWNER='***' AIRFLOW_CTX_DAG_ID='pizza_order_dag' AIRFLOW_CTX_TASK_ID='confirm_order_task' AIRFLOW_CTX_EXECUTION_DATE='2023-12-21T21:43:09.440852+00:00' AIRFLOW_CTX_TRY_NUMBER='1' AIRFLOW_CTX_DAG_RUN_ID='manual__2023-12-21T21:43:09.440852+00:00'
[2023-12-21T21:43:12.285+0000] {taskinstance.py:1937} ERROR - Task failed with exception
Traceback (most recent call last):
  File "/home/airflow/.local/lib/python3.8/site-packages/airflow/decorators/base.py", line 221, in execute
    return_value = super().execute(context)
  File "/home/airflow/.local/lib/python3.8/site-packages/airflow/operators/python.py", line 192, in execute
    return_value = self.execute_callable()
  File "/home/airflow/.local/lib/python3.8/site-packages/airflow/operators/python.py", line 209, in execute_callable
    return self.python_callable(*self.op_args, **self.op_kwargs)
  File "/opt/airflow/dags/pizza_order_dag.py", line 62, in confirm_order
    bot.send_message(chat_id=str(chat_id), text=message)
  File "/home/airflow/.local/lib/python3.8/site-packages/telebot/__init__.py", line 1541, in send_message
    apihelper.send_message(
  File "/home/airflow/.local/lib/python3.8/site-packages/telebot/apihelper.py", line 266, in send_message
    return _make_request(token, method_url, params=payload, method='post')
  File "/home/airflow/.local/lib/python3.8/site-packages/telebot/apihelper.py", line 164, in _make_request
    json_result = _check_result(method_name, result)
  File "/home/airflow/.local/lib/python3.8/site-packages/telebot/apihelper.py", line 191, in _check_result
    raise ApiTelegramException(method_name, result, result_json)
telebot.apihelper.ApiTelegramException: A request to the Telegram API was unsuccessful. Error code: 400. Description: Bad Request: chat not found
[2023-12-21T21:43:12.298+0000] {taskinstance.py:1400} INFO - Marking task as FAILED. dag_id=pizza_order_dag, task_id=confirm_order_task, execution_date=20231221T214309, start_date=20231221T214311, end_date=20231221T214312
[2023-12-21T21:43:12.311+0000] {standard_task_runner.py:104} ERROR - Failed to execute job 59 for task confirm_order_task (A request to the Telegram API was unsuccessful. Error code: 400. Description: Bad Request: chat not found; 1012)
[2023-12-21T21:43:12.345+0000] {local_task_job_runner.py:228} INFO - Task exited with return code 1
[2023-12-21T21:43:12.359+0000] {taskinstance.py:2778} INFO - 0 downstream tasks scheduled from follow-on schedule check
