[2023-12-21T22:08:43.251+0000] {taskinstance.py:1159} INFO - Dependencies all met for dep_context=non-requeueable deps ti=<TaskInstance: pizza_order_dag.confirm_order_task 2023-12-21T22:08:40.877Z [queued]>
[2023-12-21T22:08:43.260+0000] {taskinstance.py:1159} INFO - Dependencies all met for dep_context=requeueable deps ti=<TaskInstance: pizza_order_dag.confirm_order_task 2023-12-21T22:08:40.877Z [queued]>
[2023-12-21T22:08:43.261+0000] {taskinstance.py:1361} INFO - Starting attempt 1 of 1
[2023-12-21T22:08:43.273+0000] {taskinstance.py:1382} INFO - Executing <Task(_PythonDecoratedOperator): confirm_order_task> on 2023-12-21 22:08:40.877000+00:00
[2023-12-21T22:08:43.278+0000] {standard_task_runner.py:57} INFO - Started process 1463 to run task
[2023-12-21T22:08:43.280+0000] {standard_task_runner.py:84} INFO - Running: ['***', 'tasks', 'run', 'pizza_order_dag', 'confirm_order_task', '2023-12-21T22:08:40.877Z', '--job-id', '81', '--raw', '--subdir', 'DAGS_FOLDER/pizza_order_dag.py', '--cfg-path', '/tmp/tmpx4peykzo']
[2023-12-21T22:08:43.281+0000] {standard_task_runner.py:85} INFO - Job 81: Subtask confirm_order_task
[2023-12-21T22:08:43.321+0000] {task_command.py:416} INFO - Running <TaskInstance: pizza_order_dag.confirm_order_task 2023-12-21T22:08:40.877Z [running]> on host 20e184a2eb37
[2023-12-21T22:08:43.399+0000] {taskinstance.py:1662} INFO - Exporting env vars: AIRFLOW_CTX_DAG_OWNER='***' AIRFLOW_CTX_DAG_ID='pizza_order_dag' AIRFLOW_CTX_TASK_ID='confirm_order_task' AIRFLOW_CTX_EXECUTION_DATE='2023-12-21T22:08:40.877000+00:00' AIRFLOW_CTX_TRY_NUMBER='1' AIRFLOW_CTX_DAG_RUN_ID='2023-12-21T22:08:40.877Z'
[2023-12-21T22:08:44.084+0000] {taskinstance.py:1937} ERROR - Task failed with exception
Traceback (most recent call last):
  File "/home/airflow/.local/lib/python3.8/site-packages/airflow/decorators/base.py", line 221, in execute
    return_value = super().execute(context)
  File "/home/airflow/.local/lib/python3.8/site-packages/airflow/operators/python.py", line 192, in execute
    return_value = self.execute_callable()
  File "/home/airflow/.local/lib/python3.8/site-packages/airflow/operators/python.py", line 209, in execute_callable
    return self.python_callable(*self.op_args, **self.op_kwargs)
  File "/opt/airflow/dags/pizza_order_dag.py", line 56, in confirm_order
    bot.send_message(chat_id='435723655', text=f'{order_set[0].pizza.description}')
  File "/home/airflow/.local/lib/python3.8/site-packages/django/db/models/query.py", line 450, in __getitem__
    return qs._result_cache[0]
IndexError: list index out of range
[2023-12-21T22:08:44.095+0000] {taskinstance.py:1400} INFO - Marking task as FAILED. dag_id=pizza_order_dag, task_id=confirm_order_task, execution_date=20231221T220840, start_date=20231221T220843, end_date=20231221T220844
[2023-12-21T22:08:44.107+0000] {standard_task_runner.py:104} ERROR - Failed to execute job 81 for task confirm_order_task (list index out of range; 1463)
[2023-12-21T22:08:44.137+0000] {local_task_job_runner.py:228} INFO - Task exited with return code 1
[2023-12-21T22:08:44.150+0000] {taskinstance.py:2778} INFO - 0 downstream tasks scheduled from follow-on schedule check
