[2023-12-21T22:15:39.975+0000] {taskinstance.py:1159} INFO - Dependencies all met for dep_context=non-requeueable deps ti=<TaskInstance: pizza_order_dag.confirm_order_task manual__2023-12-21T22:15:38.238213+00:00 [queued]>
[2023-12-21T22:15:39.984+0000] {taskinstance.py:1159} INFO - Dependencies all met for dep_context=requeueable deps ti=<TaskInstance: pizza_order_dag.confirm_order_task manual__2023-12-21T22:15:38.238213+00:00 [queued]>
[2023-12-21T22:15:39.985+0000] {taskinstance.py:1361} INFO - Starting attempt 1 of 1
[2023-12-21T22:15:39.998+0000] {taskinstance.py:1382} INFO - Executing <Task(_PythonDecoratedOperator): confirm_order_task> on 2023-12-21 22:15:38.238213+00:00
[2023-12-21T22:15:40.003+0000] {standard_task_runner.py:57} INFO - Started process 1574 to run task
[2023-12-21T22:15:40.005+0000] {standard_task_runner.py:84} INFO - Running: ['***', 'tasks', 'run', 'pizza_order_dag', 'confirm_order_task', 'manual__2023-12-21T22:15:38.238213+00:00', '--job-id', '83', '--raw', '--subdir', 'DAGS_FOLDER/pizza_order_dag.py', '--cfg-path', '/tmp/tmp1p9ibzzo']
[2023-12-21T22:15:40.006+0000] {standard_task_runner.py:85} INFO - Job 83: Subtask confirm_order_task
[2023-12-21T22:15:40.043+0000] {task_command.py:416} INFO - Running <TaskInstance: pizza_order_dag.confirm_order_task manual__2023-12-21T22:15:38.238213+00:00 [running]> on host 20e184a2eb37
[2023-12-21T22:15:40.117+0000] {taskinstance.py:1662} INFO - Exporting env vars: AIRFLOW_CTX_DAG_OWNER='***' AIRFLOW_CTX_DAG_ID='pizza_order_dag' AIRFLOW_CTX_TASK_ID='confirm_order_task' AIRFLOW_CTX_EXECUTION_DATE='2023-12-21T22:15:38.238213+00:00' AIRFLOW_CTX_TRY_NUMBER='1' AIRFLOW_CTX_DAG_RUN_ID='manual__2023-12-21T22:15:38.238213+00:00'
[2023-12-21T22:15:40.760+0000] {taskinstance.py:1937} ERROR - Task failed with exception
Traceback (most recent call last):
  File "/home/airflow/.local/lib/python3.8/site-packages/airflow/decorators/base.py", line 221, in execute
    return_value = super().execute(context)
  File "/home/airflow/.local/lib/python3.8/site-packages/airflow/operators/python.py", line 192, in execute
    return_value = self.execute_callable()
  File "/home/airflow/.local/lib/python3.8/site-packages/airflow/operators/python.py", line 209, in execute_callable
    return self.python_callable(*self.op_args, **self.op_kwargs)
  File "/opt/airflow/dags/pizza_order_dag.py", line 46, in confirm_order
    order = Order.objects.get(order_order_id=order_id)
  File "/home/airflow/.local/lib/python3.8/site-packages/django/db/models/manager.py", line 87, in manager_method
    return getattr(self.get_queryset(), name)(*args, **kwargs)
  File "/home/airflow/.local/lib/python3.8/site-packages/django/db/models/query.py", line 623, in get
    clone = self._chain() if self.query.combinator else self.filter(*args, **kwargs)
  File "/home/airflow/.local/lib/python3.8/site-packages/django/db/models/query.py", line 1436, in filter
    return self._filter_or_exclude(False, args, kwargs)
  File "/home/airflow/.local/lib/python3.8/site-packages/django/db/models/query.py", line 1454, in _filter_or_exclude
    clone._filter_or_exclude_inplace(negate, args, kwargs)
  File "/home/airflow/.local/lib/python3.8/site-packages/django/db/models/query.py", line 1461, in _filter_or_exclude_inplace
    self._query.add_q(Q(*args, **kwargs))
  File "/home/airflow/.local/lib/python3.8/site-packages/django/db/models/sql/query.py", line 1546, in add_q
    clause, _ = self._add_q(q_object, self.used_aliases)
  File "/home/airflow/.local/lib/python3.8/site-packages/django/db/models/sql/query.py", line 1577, in _add_q
    child_clause, needed_inner = self.build_filter(
  File "/home/airflow/.local/lib/python3.8/site-packages/django/db/models/sql/query.py", line 1427, in build_filter
    lookups, parts, reffed_expression = self.solve_lookup_type(arg, summarize)
  File "/home/airflow/.local/lib/python3.8/site-packages/django/db/models/sql/query.py", line 1237, in solve_lookup_type
    _, field, _, lookup_parts = self.names_to_path(lookup_splitted, self.get_meta())
  File "/home/airflow/.local/lib/python3.8/site-packages/django/db/models/sql/query.py", line 1725, in names_to_path
    raise FieldError(
django.core.exceptions.FieldError: Cannot resolve keyword 'order_order_id' into field. Choices are: id, order_id, orderitem, unprocessed, user, user_id
[2023-12-21T22:15:40.772+0000] {taskinstance.py:1400} INFO - Marking task as FAILED. dag_id=pizza_order_dag, task_id=confirm_order_task, execution_date=20231221T221538, start_date=20231221T221539, end_date=20231221T221540
[2023-12-21T22:15:40.785+0000] {standard_task_runner.py:104} ERROR - Failed to execute job 83 for task confirm_order_task (Cannot resolve keyword 'order_order_id' into field. Choices are: id, order_id, orderitem, unprocessed, user, user_id; 1574)
[2023-12-21T22:15:40.821+0000] {local_task_job_runner.py:228} INFO - Task exited with return code 1
[2023-12-21T22:15:40.835+0000] {taskinstance.py:2778} INFO - 0 downstream tasks scheduled from follow-on schedule check
